Workbook

Sheet 판정대시보드
A1: SPC 자동 판정 · 해석 대시보드
A2: Stator Assys(MV후륜) | 단계: mass_production
A4: 공정상태 | B4: 정규성 | C4: 공정능력 | D4: 관리도 적용
A5: 판정불가 | B5: 비정규 | C5: 부족 | D5: 불가
A7: ▶ 우선 조치: 데이터 재수집
A9: 회사 기준 판정 · 후속조치 체크
A10: ○ | B10: 관리용 관리도 적용 | C10: 불가
A11: ● | B11: 데이터 재수집 필요 | C11: 필요
A12: ● | B12: 공정 개선 필요 | C12: 필요
A13: — | B13: 관리한계 재설정 | C13: 해당 없음
A14: — | B14: 관리계획서 검토 | C14: 해당 없음
A15: — | B15: 작업표준 검토 | C15: 해당 없음
A16: — | B16: 봉쇄 검토 | C16: 해당 없음
A17: — | B17: 전수검사 검토 | C17: 해당 없음
A18: — | B18: 고객 예외 검토 | C18: 해당 없음
A19: 권고 조치: 데이터 재수집 → 중심 이동
A21: 판정 근거 (Decision Log)
A22: 우선순위 | B22: 규칙 ID | C22: 판정 내용
A23: 5 | B23: R_CHART_FIRST | C23: R chart unstable -> mean chart interpretation deferred
A24: 6 | B24: DEPLOY_BLOCKED | C24: process not in stable state -> operational control chart deployment not allowed
A25: 14 | B25: NORMality_STRICT | C25: strict_company_mode + non-normal -> cause analysis, action, recollection required
A26: 15 | B26: CAPABILITY_CENTERING | C26: Cp>=1.33 and Cpk<1.33 -> centering improvement recommended
A27: 30 | B27: STAGE_CAPABILITY | C27: stage=mass_production -> CpCpk rule applied (threshold width=1.33, center=1.33)
A29: SPC 전문가 해석
A30: ■ 경영진 요약
A31: 본 공정은 해석용 관리도 기준으로 안정상태가 확인되지 않았습니다. 특히 산포 관리도에서 이상신호가 확인되어 현재 관리한계선을 기반으로 한 현장 운영은 부적절합니다. 이 경우 평균 위치 해석보다 산포 원인 제거가 우선이며, 공정 안정화 후 재수집 데이터를 기준으로 관리한계선을 다시 설정해야 합니다. 공정 산포(폭)는 기준을 만족하나 중심 지수가 부족합니다. 산포 개선보다 규격 중심 대비 평균 위치 조정(centering)이 우선 과제입니다.
A33: ■ 관리도 해석
A34: 관리도에서 관리한계 이탈, 중심선 편향, 과도한 산포 등 4건의 이상 패턴이 감지되었습니다. R(산포) 관리도 불안정 — 평균 관리도 해석 보류, 산포 원인 제거 우선
A36: ■ 정규성 해석
A37: 데이터가 정규분포 가정에서 벗어났습니다. 단순 p-value 판정에 그치지 말고 원인을 파악하고 조치한 뒤 데이터를 재수집하여 재분석하십시오. (검정: Shapiro-Wilk, p=0.0416, QQ: 정규확률도 직선성 양호(R²≈0.976))
A39: ■ 공정능력 해석
A40: 현재 지표는 Cp/Cpk 기준 잠재 공정능력 해석이 중심입니다. 공정 산포(폭)는 기준을 만족하나 중심 지수가 부족합니다. 산포 개선보다 규격 중심 대비 평균 위치 조정(centering)이 우선 과제입니다. Cp=1.394, Cpk=1.167 (기준 Cp/Cpk≥1.33)
A42: ■ 후속조치 가이드
A43: 우선 조치: 데이터 재수집 → 중심 이동
A45: ■ 현장 실무자 해석
... A48: AIAG-VDA 확장 점검
A49: Pre-control 권고 | B49: X-bar 계열 운용 — Pre-control Chart는 보조 수단으로 검토
A50: 기계성능(Cm/Cmk) 필요 | B50: 아니오
A51: 기계성능 모듈 | B51: Cm/Cmk calculation module not implemented yet.
A52: 리포트 완전성 | B52: 완전
...

Sheet 용어_초보가이드
A1: SPC · 공정능력 — 초보자용 용어 설명
A2: 보고서를 처음 보실 때 이 시트부터 읽으시면 됩니다. §6 산출식은 본 프로그램이 실제로 사용하는 계산식(AIAG/Minitab 기준)입니다. 검증_수식연계 시트에서 Excel로 같은 식을 재현할 수 있습니다.
A4: 1. 기본 개념
A5: 용어 | B5: 한 줄로 이해하기 | C5: 조금 더 자세히 | D5: 보고서에서 보는 곳
A6: SPC | B6: 공정이 안정적인지·규격을 지키는지 숫자와 차트로 보는 방법 | C6: Statistical Process Control. 측정값을 시간·LOT별로 모아 관리도와 공정능력으로 판단합니다. | D6: 종합 시트 전체
A7: USL / LSL | B7: 규격 상한·하한 (이 범위 안이면 합격) | C7: Upper/Lower Specification Limit. 도면·검사기준에서 정한 허용 범위입니다. | D7: 종합 5·6항, 공정능력 시트
A8: Subgroup (부군) | B8: 관리도용으로 묶은 측정값 한 묶음 (예: 연속 5개) | C8: 같은 조건에서 연속 측정한 n개를 1그룹으로 보고 Xbar, R(또는 S)을 계산합니다. | D8: Subgroup통계 (Xbar·R)
A9: σ (시그마) | B9: 데이터가 얼마나 퍼져 있는지 나타내는 산포 | C9: 표준편차. 값이 클수록 측정값이 넓게 퍼져 있습니다. | D9: 공정능력 시트, 검증 시트
A11: 2. 공정능력 지표 (Cp · Cpk 등)
A12: 용어 | B12: 한 줄로 이해하기 | C12: 조금 더 자세히 | D12: 보고서에서 보는 곳
A13: Cp | B13: 규격 폭에 비해 산포가 얼마나 좁은지 (공정 폭) | C13: Cp = (USL−LSL) / (6σ_within). σ_within은 부군 내·부군 간 변동을 반영한 공정 산포입니다. 평균 위치는 보지 않고 「퍼짐」만 봅니다. | D13: 종합 우측 표, 공정능력 시트
A14: Cpk | B14: 규격 중심에 얼마나 잘 맞춰져 있는지 (실질 능력) | C14: Cpk = min(Cpu, Cpl). 평균이 USL·LSL 중 한쪽에 치우치면 Cpk가 Cp보다 작아집니다. 현장에서는 Cpk를 가장 많이 봅니다. | D14: 종합 우측 표, 공정능력 시트
A15: Cpu / Cpl | B15: 상한·하한 각각에 대한 여유 | C15: Cpu=(USL−평균)/(3σ_within), Cpl=(평균−LSL)/(3σ_within). Cpk는 둘 중 작은 값입니다. | D15: 공정능력 시트, 검증 시트 §4
A16: Pp / Ppk | B16: 전체 데이터 산포로 본 능력 (장기·전체 변동) | C16: σ_overall(표본 전체 표준편차)을 사용합니다. Ppk가 Cpk보다 작으면 시간이 지나며 산포가 커졌거나 추가 변동이 있다는 신호일 수 있습니다. | D16: 공정능력 시트
A17: σ_within / σ_overall | B17: 단기 공정 산포 vs 전체 산포 | C17: σ_within: 관리도(R,S,MR)로 추정한 공정 산포. σ_overall: 모든 측정값의 표준편차. | D17: 검증 시트 §2·§3
A18: PPM (예상) | B18: 규격 밖으로 나갈 것으로 예상되는 불량 비율(백만분율) | C18: 정규분포를 가정해 USL·LSL 밖 확률을 추정한 값입니다. | D18: 종합 표, 공정능력 시트
A20: 3. 정규성 검정
A21: 용어 | B21: 한 줄로 이해하기 | C21: 조금 더 자세히 | D21: 보고서에서 보는 곳
A22: 정규성 검정 | B22: 데이터가 「종 모양(정규분포)」에 가까운지 통계적으로 확인 | C22: 공정능력·PPM 해석은 정규분포 가정에 기대는 경우가 많아, 먼저 확인하는 단계입니다. | D22: 정규성검정 시트, 종합 15·16항
A23: p-value (p값) | B23: 「우연이 아니다」의 정도 — 작을수록 정규분포와 다르다 | C23: p가 작으면(예: 0.05 미만) 정규분포라고 보기 어렵다고 판단합니다. p가 크면(예: 0.05 이상) 정규와 크게 다르지 않다고 「일단」 받아들이는 경우가 많습니다. | D23: 정규성검정 시트 p_value 열
A24: 유의수준 α (알파) | B24: p-value와 비교하는 기준선 (보통 0.05 = 5%) | C24: p-value < α 이면 「정규가 아니다」로 판정하는 일반적 규칙입니다. α=0.05는 「100번 중 5번까지는 우연히 나올 수 있는 차이」를 허용한다는 뜻에 가깝습니다. | D24: 정규성검정 시트 유의수준
A25: Shapiro-Wilk | B25: 표본이 정규분포인지 검정하는 대표적인 방법 | C25: 본 프로그램은 표본 수에 따라 Shapiro-Wilk 또는 D'Agostino 검정을 사용합니다. | D25: 정규성검정 시트 검정방법
A26: 정규 / 비정규 판정 | B26: 보고서에 표시된 최종 결론 | C26: p-value ≥ α 이면 「정규」, 그렇지 않으면 「비정규」로 표시합니다. 비정규일 때는 변환·다른 분석·원인 조사를 검토할 수 있습니다. | D26: 종합 16항
A28: 4. 관리도
A29: 용어 | B29: 한 줄로 이해하기 | C29: 조금 더 자세히 | D29: 보고서에서 보는 곳
A30: 관리도 | B30: 시간·순서에 따른 측정값이 안정적인지 보는 차트 | C30: 평균이 갑자기 튀거나 산포가 커지면 「특별 원인」을 찾도록 돕습니다. | D30: 종합 차트, 관리한계 시트
A31: CL / UCL / LCL | B31: 중심선·관리 상한·관리 하한 | C31: CL(Center Line): 평균 수준. UCL/LCL: 통계적으로 기대되는 변동 범위 밖이면 이상 신호로 봅니다. | D31: 관리한계 시트, 종합 관리도 차트
A32: X-bar (X̄) 차트 | B32: 부군별 평균이 안정적인지 확인 | C32: 공정 평균이 서서히 변하거나 갑자기 변했는지 봅니다. | D32: Subgroup통계 (Xbar·R), 종합 차트
A33: R / S 차트 | B33: 부군 내 산포(범위·표준편차)가 안정적인지 확인 | C33: R=최대−최소, S=표준편차. 산포가 커지면 공정이 불안정해졌을 수 있습니다. | D33: Subgroup통계, 관리한계
A34: I-MR 차트 | B34: 개별 측정값·이동범위 차트 (부군 없을 때) | C34: 한 점씩 측정할 때 사용. I=개별값, MR=연속 두 점 차이의 절대값. | D34: Individual통계, 관리한계
A35: 관리內 / 관리外 | B35: 관리도 점이 한계 안/밖인지 요약 | C35: 관리外: UCL 또는 LCL 밖에 점이 있음 → 원인 조사·조치 검토. | D35: 종합 17항
A37: 5. 채취·데이터
A38: 용어 | B38: 한 줄로 이해하기 | C38: 조금 더 자세히 | D38: 보고서에서 보는 곳
A39: 채취표본 | B39: 이번 분석에 실제로 사용한 측정 데이터 | C39: MES/QMS에서 필터·샘플링한 결과입니다. LOT·일자·교대 정보가 있을 수 있습니다. | D39: 채취표본 시트
A40: 일자 랜덤 채취 | B40: 날짜별로 골고루 뽑아 편향을 줄이는 방식 | C40: 특정 하루 데이터만 몰리지 않도록 설계된 샘플링입니다. | D40: 채취표본, 종합 메타
A41: 검증_수식연계 | B41: 프로그램 결과와 Excel 수식이 같은지 확인하는 시트 | C41: OK/NG로 일치 여부를 표시합니다. 수식 셀을 누르면 어떤 데이터를 참조하는지 볼 수 있습니다. | D41: 검증_수식연계 시트
A43: 6. 주요 산출값 산출식 (본 프로그램 적용)
A44: 기호: X̄=평균, σ=표준편차, n=부군 크기, N=총 측정 개수, USL/LSL=규격 상·하한. 상수 A2,A3,d2,c4 등은 부군 크기 n에 따라 AIAG 표에서 자동 적용됩니다.
A46: 6-1. 기초 통계 (모든 분석)
A47: 산출값 | B47: 산출식 | C47: 변수·기호 설명 | D47: 데이터 출처 | E47: 검증 시트
...

Sheet 검증_수식연계
A1: SPC 산출값 검증 · 데이터·수식 연계
A2: 프로그램 산출값(B열)과 Excel 수식(C열→D열 계산)을 비교합니다. 수식은 영문 Excel 표준 형식(AVERAGE, STDEV.S, MIN 등)이며, 채취표본 시트의 측정값 열·데이터 행 수는 보고서 생성 시 자동 탐지됩니다. 측정값 자동 연결: 채취표본!$M$2:$M$126 [헤더=value]
A4: 1. 보고서 데이터 연계 맵
A5: 종합/요약 항목 | B5: 출처 시트 | C5: Excel 참조 | D5: 설명
A6: 표본·평균·σ_overall | B6: 채취표본 | C6: 채취표본!$M$2:$M$126 | D6: 측정값 열 자동(value)
A7: Subgroup Xbar / R / S | B7: Subgroup통계 | C7: Xbar·R 또는 S | D7: X-bar 관리도
A8: I / MR | B8: Individual통계 | C8: I·MR 열 | D8: I-MR 관리도
A9: 관리한계 | B9: 관리한계 | C9: 차트·항목별 행 | D9: AIAG 상수
A10: Cp/Cpk/Pp/Ppk | B10: 공정능력 | C10: 행200 기준값·수식 | D10: 본 시트 §4
A11: 정규성 | B11: 정규성검정 | C11: 정규성검정!$C$2 | D11: p-value 열 자동 탐지
A13: 2. 채취표본 기반 통계 (Excel 재계산)
A14: 항목 | B14: 프로그램 산출 | C14: Excel 검증 수식 | D14: Excel 계산값 | E14: 차이 | F14: 일치 | G14: 연계 시트/범위
A15: 표본수 n | B15: 125 | C15: =COUNT(채취표본!$M$2:$M$126) | D15: =C15 | E15: =ABS(B15-D15) | F15: =IF(ABS(B15-D15)<0.0001,"OK","NG") | G15: 채취표본!$M$2:$M$126
A16: 평균 Mean | B16: -0.098 | C16: =AVERAGE(채취표본!$M$2:$M$126) | D16: =C16 | E16: =ABS(B16-D16) | F16: =IF(ABS(B16-D16)<0.0001,"OK","NG") | G16: 채취표본!$M$2:$M$126
A17: σ_overall STDEV.S | B17: 0.1926136 | C17: =_xlfn.STDEV.S(채취표본!$M$2:$M$126) | D17: =C17 | E17: =ABS(B17-D17) | F17: =IF(ABS(B17-D17)<0.0001,"OK","NG") | G17: 채취표본!$M$2:$M$126
A19: 3. 관리도 한계 검증
A20: 항목 | B20: 프로그램 산출 | C20: Excel 검증 수식 | D20: Excel 계산값 | E20: 차이 | F20: 일치 | G20: 연계 시트/범위
A21: X̿ (Xbar-bar) | B21: -0.098 | C21: =AVERAGE(Subgroup통계!$B$2:$B$26) | D21: =C21 | E21: =ABS(B21-D21) | F21: =IF(ABS(B21-D21)<1e-05,"OK","NG") | G21: Subgroup통계!$B$2:$B$26
A22: R̄ | B22: 0.3336 | C22: =AVERAGE(Subgroup통계!$C$2:$C$26) | D22: =C22 | E22: =ABS(B22-D22) | F22: =IF(ABS(B22-D22)<1e-05,"OK","NG") | G22: Subgroup통계!$C$2:$C$26
A23: σ_within=R̄/d2 | B23: 0.14342218 | C23: =AVERAGE(Subgroup통계!$C$2:$C$26)/2.326 | D23: =C23 | E23: =ABS(B23-D23) | F23: =IF(ABS(B23-D23)<1e-05,"OK","NG") | G23: d2=2.326
A24: Xbar UCL | B24: 0.0944872 | C24: =AVERAGE(Subgroup통계!$B$2:$B$26)+0.577*AVERAGE(Subgroup통계!$C$2:$C$26) | D24: =C24 | E24: =ABS(B24-D24) | F24: =IF(ABS(B24-D24)<1e-05,"OK","NG") | G24: A2=0.577
A27: 4. 공정능력 지표 검증 (AIAG 수식)
A28: 항목 | B28: 프로그램 산출 | C28: Excel 검증 수식 | D28: Excel 계산값 | E28: 차이 | F28: 일치 | G28: 연계 시트/범위
A29: Cp (수식검증) | B29: 1.3944844 | C29: =IF((6*$B$203)=0,0,(($B$200-$B$201))/(6*$B$203)) | D29: =C29 | E29: =ABS(B29-D29) | F29: =IF(ABS(B29-D29)<0.0002,"OK","NG") | G29: 6*sigma_within; sheet=공정능력!$F$2
A30: Cp (시트교차) | B30: 1.3944844 | C30: =공정능력!$F$2 | D30: =C30 | E30: =ABS(B30-D30) | F30: =IF(ABS(B30-D30)<0.0002,"OK","NG") | G30: 공정능력 row 2
A31: Cpu (수식검증) | B31: 1.6222502 | C31: =IF((3*$B$203)=0,0,(($B$200-$B$202))/(3*$B$203)) | D31: =C31 | E31: =ABS(B31-D31) | F31: =IF(ABS(B31-D31)<0.0002,"OK","NG") | G31: 3*sigma_within; sheet=공정능력!$J$2
A32: Cpu (시트교차) | B32: 1.6222502 | C32: =공정능력!$J$2 | D32: =C32 | E32: =ABS(B32-D32) | F32: =IF(ABS(B32-D32)<0.0002,"OK","NG") | G32: 공정능력 row 2
A33: Cpl (수식검증) | B33: 1.1667186 | C33: =IF((3*$B$203)=0,0,(($B$202-$B$201))/(3*$B$203)) | D33: =C33 | E33: =ABS(B33-D33) | F33: =IF(ABS(B33-D33)<0.0002,"OK","NG") | G33: 3*sigma_within; sheet=공정능력!$K$2
A34: Cpl (시트교차) | B34: 1.1667186 | C34: =공정능력!$K$2 | D34: =C34 | E34: =ABS(B34-D34) | F34: =IF(ABS(B34-D34)<0.0002,"OK","NG") | G34: 공정능력 row 2
A35: Cpk (수식검증) | B35: 1.1667186 | C35: =MIN(IF((3*$B$203)=0,0,(($B$200-$B$202))/(3*$B$203)),IF((3*$B$203)=0,0,(($B$202-$B$201))/(3*$B$203))) | D35: =C35 | E35: =ABS(B35-D35) | F35: =IF(ABS(B35-D35)<0.0002,"OK","NG") | G35: min(Cpu,Cpl); sheet=공정능력!$G$2
A36: Cpk (시트교차) | B36: 1.1667186 | C36: =공정능력!$G$2 | D36: =C36 | E36: =ABS(B36-D36) | F36: =IF(ABS(B36-D36)<0.0002,"OK","NG") | G36: 공정능력 row 2
A37: Pp (수식검증) | B37: 1.0383483 | C37: =IF((6*$B$204)=0,0,(($B$200-$B$201))/(6*$B$204)) | D37: =C37 | E37: =ABS(B37-D37) | F37: =IF(ABS(B37-D37)<0.0002,"OK","NG") | G37: 6*sigma_overall; sheet=공정능력!$H$2
A38: Pp (시트교차) | B38: 1.0383483 | C38: =공정능력!$H$2 | D38: =C38 | E38: =ABS(B38-D38) | F38: =IF(ABS(B38-D38)<0.0002,"OK","NG") | G38: 공정능력 row 2
A39: Ppk (수식검증) | B39: 0.86875138 | C39: =MIN(IF((3*$B$204)=0,0,(($B$200-$B$202))/(3*$B$204)),IF((3*$B$204)=0,0,(($B$202-$B$201))/(3*$B$204))) | D39: =C39 | E39: =ABS(B39-D39) | F39: =IF(ABS(B39-D39)<0.0002,"OK","NG") | G39: min(Ppu,Ppl); sheet=공정능력!$I$2
A40: Ppk (시트교차) | B40: 0.86875138 | C40: =공정능력!$I$2 | D40: =C40 | E40: =ABS(B40-D40) | F40: =IF(ABS(B40-D40)<0.0002,"OK","NG") | G40: 공정능력 row 2
A42: 5. 정규성·시트 교차참조
A43: 항목 | B43: 프로그램 산출 | C43: Excel 검증 수식 | D43: Excel 계산값 | E43: 차이 | F43: 일치 | G43: 연계 시트/범위
A44: p-value | B44: 0.04156946 | C44: =정규성검정!$C$2 | D44: =C44 | E44: =ABS(B44-D44) | F44: =IF(ABS(B44-D44)<1e-06,"OK","NG") | G44: 정규성검정!$C$2 자동 참조. Excel 표준 함수로 Shapiro-Wilk p-value 계산 불가 (SWTEST/SHAPIRO 없음, Real Statistics 등 애드인만 별도 지원).
A45: 표본수 n | B45: 125 | C45: =COUNT(채취표본!$M$2:$M$126) | D45: =C45 | E45: =ABS(B45-D45) | F45: =IF(ABS(B45-D45)<0.0001,"OK","NG") | G45: 채취표본
A46: 관리한계 Xbar UCL | B46: 0.0944872 | C46: =SUMIFS('관리한계'!$C$2:$C$7,'관리한계'!$A$2:$A$7,"Xbar",'관리한계'!$B$2:$B$7,"UCL") | D46: =C46 | E46: =ABS(B46-D46) | F46: =IF(ABS(B46-D46)<1e-05,"OK","NG") | G46: 관리한계
...

Sheet 종합
A1: SPC 및 공정능력 연구 보고서
A2: AIAG / VDA SPC Harmonized Standard — Process Capability Study
A3: ▣ 자동 판정 요약
A4: 공정: 판정불가 | D4: 정규성: 비정규 | G4: 공정능력: 부족 | J4: 관리도: 불가
A5: 우선 조치: 데이터 재수집
A7: 1. 공정명 | B7: - | F7: 지표 | G7: 값
A8: 2. 설비/라인 | B8: - | F8: USL | G8: 0.6
A9: 3. 품목 | B9: Stator Assys(MV후륜) | F9: LSL | G9: -0.6
A10: 데이터 출처 | B10: 검사데이터_조회_터미널단자높이_260504~0602.xlsx | F10: Mean | G10: -0.098000
A11: 4. 특성(검사항목) | B11: - | F11: Std(within) | G11: 0.143422
A12: 5. USL | B12: 0.6 | F12: Std(overall) | G12: 0.192614
A13: 6. LSL | B13: -0.6 | F13: Cp | G13: 1.3945
A14: 7. 표본수 | B14: 125 | F14: Cpk | G14: 1.1667
A15: 8. Subgroup 크기 | B15: 5 | F15: Pp | G15: 1.0383
A16: 9. 관리도 유형 | B16: X-bar R | F16: Ppk | G16: 0.8688
A17: 10. 분석일시 | B17: 2026-06-09 17:44 | F17: 예상 PPM | G17: 233.06
A18: 15. 정규성 검정 | B18: Shapiro-Wilk, p=0.0416 | F18: P% > USL | G18: 0.0001%
A19: 16. 정규성 판정 | B19: 비정규 | F19: P% < LSL | G19: 0.0232%
A20: 17. 관리상태 | B20: 관리外
A21: 18. 채취 방식 | B21: 일자·LOT·교대 블록 랜덤
A59: 20. Conclusions / Recommendations (차트별 품질 전문가 점검)
A60: 【종합 판정】 4종 차트(히스토그램·Raw·정규확률도·Xbar-R Control Chart) 통합 검토. 요약 플래그: 관리外, 비정규. 표본 n=125, 관리도=X-bar R. 아래는 차트별 주의·점검·권고입니다. ■ 11. Histogram (히스토그램) [주의] ※ 주의·해석 · 평균이 규격 중심 대비 -0.0980 이탈 — 히스토그램 피크가 USL/LSL 중 한쪽에 치우쳤는지 확인 · Cp(1.394) 대비 Cpk(1.167) 저하 — 변동은 충분하나 평균 위치(산포 중심) 불량 신호 · 정규성 미충족(p=0.0416) — 히스토그램의 정규 곡선 오버레이는 참고용, Pp/Ppk 해석에 주의 ※ 점검 항목 · USL/LSL 대비 분포 폭·위치: 규격 내 집중 vs 양끝·한쪽 쏠림 · 정규분포 곡선 대비 실제 막대: 꼬리 두께, 다봉(혼합 공정), 절단(측정 한계·반올림) · 히스토그램 bin 수에 따른 형상 왜곡 여부(표본수 대비 bin 과다/과소) · 평균선·규격한계와 피크 위치 일치 여부(목표값 대비 편향) ※ 권고 조치 · 이상 구간 LOT·교대·설비·금형 등 메타데이터와 막대 구간 교차 확인 · 비정규·다봉 시 로그/Box-Cox 변환 또는 비정규 공정능력 지표 병행 검토 ■ 12. Raw Value Chart (개별값 시계열) [조치] ※ 주의·해석 · 순번 122 부근 급격 변동(Δ=0.7600) — 셋업 변경·이상치·측정 오류 점검 · 평균±3σ 벗어난 순번: 53 (개별값 관점 이상 후보) · 관리도 기준 관리外 subgroup/포인트: 5, 11, 12, 25 — Raw 차트 동일 구간 연계 확인 ※ 점검 항목 · 시간·순번 방향 패턴: 상승/하락/주기(사이클)·계단 변화(조건 변경) · 단발 스파이크 vs 연속 밴드 이탈(특별원인 vs 공통원인 후보) · 측정 시스템·센서·영점 드리프트, 샘플링 누락/중복 · 관리도 OOC 시점과 Raw 차트 위치 일치 여부 ※ 권고 조치 · OOC·급변 순번의 작업조건·LOT·설비 이력과 교차 검증 · 추세 지속 시 예방보전·공정 파라미터 재튜닝 후 재채취 ■ 13. Normal Probability Plot (정규확률도) [주의] ※ 주의·해석 · Shapiro-Wilk p-value=0.0416 (비정규), NPP 적합 R²≈0.976 · 검정은 비정규이나 확률도는 거의 직선 — 중앙부만 정규·꼬리 이탈(heavy tail) 가능 ※ 점검 항목 · S자·곡선: 왜도 / 양 끝 동시 이탈: 첨도·이상치 · 하단·상단 꼬리만 벗어남: 측정 한계·절단·혼합 집단 · 이론 직선 대비 체계적 곡률: 변환(로그·Box-Cox) 필요 여부 · 히스토그램·정규성 검정 결과와 삼각 교차 확인 ※ 권고 조치 · 꼬리 이탈 시 Winsorize/이상치 제거 전후 p-value·공정능력 비교 · 비정규 확정 시 Johnson/분포 피팅 또는 비모수 규격 만족률 검토 ■ 14. Xbar-R Control Chart [조치] ※ 주의·해석 · Xbar(또는 I) 관리外: subgroup/point 5, 11, 12, 25 — 평균(위치) 특별원인 후보 · R 차트 UCL 초과: 9, 11, 15, 25 — 산포·변동 증가(공구·고정·원료) 후보 ※ 점검 항목 · Subgroup n=5: 부군 내 연속성·동일 LOT/조건 유지 여부(채취 규칙 준수) · Xbar 이탈 + R/S 정상: 평균 이동(위치) / R·S 이탈 + Xbar 정상: 변동 증가 분리 해석 · Western Electric: 3σ 초과, 2σ 구간 2/3 연속, 7연속 증가·감소, 7연속 한쪽(규칙 1~4) 육안 점검 · R/S 하한(LCL) 근접: 측정 분해능·반올림·데이터 스택킹 의심 ※ 권고 조치 · OOC 발생 시점 전후 5W2H·변경점(4M1E) 기록, 조치 후 20~25 subgroup 재수집 · R/S만 OOC면 변동원인(고정·공구·환경), Xbar만 OOC면 평균·셋업·원료 배치 원인 우선 ■ 종합 우선 조치 1. 관리도·Raw 차트 OOC 구간 원인분석 및 조치 후 재채취·재분석 2. 비정규 분포 — NPP·히스토그램 교차 확인 후 공정능력 지표 해석·대안 검토 3. Cpk=1.167 — 고객/내부 목표(통상 1.33) 대비 여유 확보 검토 【자동 판정 요약】 공정상태: 판정불가 정규성: 비정규 공정능력: 부족 관리용 관리도 적용: 불가 우선 조치: 데이터 재수집 【회사 기준 판정 근거 (Decision Log)】 · [R_CHART_FIRST] R chart unstable -> mean chart interpretation deferred · [DEPLOY_BLOCKED] process not in stable state -> operational control chart deployment not allowed · [NORMality_STRICT] strict_company_mode + non-normal -> cause analysis, action, recollection required · [CAPABILITY_CENTERING] Cp>=1.33 and Cpk<1.33 -> centering improvement recommended · [STAGE_CAPABILITY] stage=mass_production -> CpCpk rule applied (threshold width=1.33, center=1.33) 【SPC 전문가 해석】 ▶ 경영진 요약: 본 공정은 해석용 관리도 기준으로 안정상태가 확인되지 않았습니다. 특히 산포 관리도에서 이상신호가 확인되어 현재 관리한계선을 기반으로 한 현장 운영은 부적절합니다. 이 경우 평균 위치 해석보다 산포 원인 제거가 우선이며, 공정 안정화 후 재수집 데이터를 기준으로 관리한계선을 다시 설정해야 합니다. 공정 산포(폭)는 기준을 만족하나 중심 지수가 부족합니다. 산포 개선보다 규격 중심 대비 평균 위치 조정(centering)이 우선 과제입니다. ▶ 실무 해석: 이번 결과는 평균이 약간 벗어난 문제라기보다 공정 흔들림이 크다는 의미에 가깝습니다. 먼저 설비 상태, 치공구, 자재, 측정 이상 여부를 점검해 산포를 키우는 원인을 줄이는 것이 우선입니다. ▶ 정규성: 데이터가 정규분포 가정에서 벗어났습니다. 단순 p-value 판정에 그치지 말고 원인을 파악하고 조치한 뒤 데이터를 재수집하여 재분석하십시오. (검정: Shapiro-Wilk, p=0.0416, QQ: 정규확률도 직선성 양호(R²≈0.976)) ▶ 공정능력: 현재 지표는 Cp/Cpk 기준 잠재 공정능력 해석이 중심입니다. 공정 산포(폭)는 기준을 만족하나 중심 지수가 부족합니다. 산포 개선보다 규격 중심 대비 평균 위치 조정(centering)이 우선 과제입니다. Cp=1.394, Cpk=1.167 (기준 Cp/Cpk≥1.33) ▶ 후속조치: 우선 조치: 데이터 재수집 → 중심 이동 【AIAG-VDA 확장 점검】 Pre-control: X-bar 계열 운용 — Pre-control Chart는 보조 수단으로 검토 기계성능(Cm/Cmk) 필요: 아니오 Cm/Cmk calculation module not implemented yet. Pp/Ppk 기준: Pp/Ppk: 전체 변동(σ_overall, ddof=1) 기반 — 개발/선행 단계 평가에 적합 Cp/Cpk 기준: Cp/Cpk: 관리도 기반 σ_within 추정 — 양산 단계 잠재 공정능력 평가에 적합 【리포트 완전성】 상태: 완전

Sheet 정규성검정
A1: 검정방법 | B1: 통계량 | C1: p_value | D1: 정규성_판정 | E1: 유의수준 | F1: 표본수
A2: Shapiro-Wilk | B2: 0.97828 | C2: 0.041569 | D2: 비정규 | E2: 0.05 | F2: 125

Sheet 관리한계
A1: 차트 | B1: 항목 | C1: 값
A2: Xbar | B2: CL | C2: -0.098
A3: Xbar | B3: UCL | C3: 0.0944872
A4: Xbar | B4: LCL | C4: -0.2904872
A5: R | B5: CL | C5: 0.3336
A6: R | B6: UCL | C6: 0.705564
A7: R | B7: LCL | C7: 0

Sheet 공정능력
A1: USL | B1: LSL | C1: 평균(Xbar) | D1: σ_within | E1: σ_overall | F1: Cp | G1: Cpk | H1: Pp | I1: Ppk | J1: Cpu | K1: Cpl | L1: 예상PPM
A2: 0.6 | B2: -0.6 | C2: -0.098 | D2: 0.143422 | E2: 0.192614 | F2: 1.3945 | G2: 1.1667 | H2: 1.0383 | I2: 0.8688 | J2: 1.6223 | K2: 1.1667 | L2: 233.06

Sheet Subgroup통계
A1: subgroup | B1: Xbar | C1: R
A2: 1 | B2: -0.138 | C2: 0.14
A3: 2 | B3: -0.014 | C3: 0.25
A4: 3 | B4: -0.176 | C4: 0.35
A5: 4 | B5: -0.17 | C5: 0.31
A6: 5 | B6: -0.338 | C6: 0.1
A7: 6 | B7: -0.17 | C7: 0.14
A8: 7 | B8: -0.018 | C8: 0.37
A9: 8 | B9: -0.128 | C9: 0.1
A10: 9 | B10: -0.036 | C10: 0.84
A11: 10 | B11: -0.172 | C11: 0.24
A12: 11 | B12: 0.098 | C12: 0.79
A13: 12 | B13: -0.344 | C13: 0.35
... A26: 25 | B26: 0.158 | C26: 0.76

Sheet 채취표본
A1: 라인 코드 | B1: 공정 코드 | C1: process | D1: 설비 코드 | E1: 품번 | F1: item | G1: lot | H1: 최종 판정 | I1: timestamp | J1: 검사 항목 순번 | K1: characteristic | L1: 스펙 체크 유형 | M1: value | N1: target | O1: lsl | P1: usl | Q1: 검사 단위 | R1: 항목별 검사결과 | S1: source | T1: subgroup_id | U1: sampling_block | V1: sampling_date | W1: sampling_strategy
A2: ST01 | B2: ST140 | C2: 터미널 높이 검사 | D2: ST01-140-01 | E2: 365301XFB0 | F2: Stator Assys(MV후륜) | G2: 365301XFB0,SFZOT5T0054 | H2: OK | I2: 46169.317 | J2: 1 | K2: 높이 측정 데이터#1 | L2: T | M2: -0.18 | R2: OK | S2: 검사데이터_조회_터미널단자높이_260504~0602 | T2: 1 | U2: 2026-05-27|야간|LOT=365301XFB0,SFZOT5T0054 | V2: 2026-05-27 | W2: date_block
A3: ST01 | B3: ST140 | C3: 터미널 높이 검사 | D3: ST01-140-01 | E3: 365301XFB0 | F3: Stator Assys(MV후륜) | G3: 365301XFB0,SFZOT5T0054 | H3: OK | I3: 46169.317 | J3: 2 | K3: 높이 측정 데이터#2 | L3: T | M3: -0.05 | R3: OK | S3: 검사데이터_조회_터미널단자높이_260504~0602 | T3: 1 | U3: 2026-05-27|야간|LOT=365301XFB0,SFZOT5T0054 | V3: 2026-05-27 | W3: date_block
A4: ST01 | B4: ST140 | C4: 터미널 높이 검사 | D4: ST01-140-01 | E4: 365301XFB0 | F4: Stator Assys(MV후륜) | G4: 365301XFB0,SFZOT5T0054 | H4: OK | I4: 46169.317 | J4: 3 | K4: 높이 측정 데이터#3 | L4: T | M4: -0.16 | R4: OK | S4: 검사데이터_조회_터미널단자높이_260504~0602 | T4: 1 | U4: 2026-05-27|야간|LOT=365301XFB0,SFZOT5T0054 | V4: 2026-05-27 | W4: date_block
A5: ST01 | B5: ST140 | C5: 터미널 높이 검사 | D5: ST01-140-01 | E5: 365301XFB0 | F5: Stator Assys(MV후륜) | G5: 365301XFB0,SFZOT5T0054 | H5: OK | I5: 46169.317 | J5: 4 | K5: 높이 측정 데이터#4 | L5: T | M5: -0.19 | R5: OK | S5: 검사데이터_조회_터미널단자높이_260504~0602 | T5: 1 | U5: 2026-05-27|야간|LOT=365301XFB0,SFZOT5T0054 | V5: 2026-05-27 | W5: date_block
A6: ST01 | B6: ST140 | C6: 터미널 높이 검사 | D6: ST01-140-01 | E6: 365301XFB0 | F6: Stator Assys(MV후륜) | G6: 365301XFB0,SFZOT5T0054 | H6: OK | I6: 46169.317 | J6: 5 | K6: 높이 측정 데이터#5 | L6: T | M6: -0.11 | R6: OK | S6: 검사데이터_조회_터미널단자높이_260504~0602 | T6: 1 | U6: 2026-05-27|야간|LOT=365301XFB0,SFZOT5T0054 | V6: 2026-05-27 | W6: date_block
A7: ST01 | B7: ST140 | C7: 터미널 높이 검사 | D7: ST01-140-01 | E7: 365301XFB0 | F7: Stator Assys(MV후륜) | G7: 365301XFB0,SFZOT610092 | H7: OK | I7: 46175.373 | J7: 1 | K7: 높이 측정 데이터#1 | L7: T | M7: -0.19 | R7: OK | S7: 검사데이터_조회_터미널단자높이_260504~0602 | T7: 2 | U7: 2026-06-02|주간|LOT=365301XFB0,SFZOT610092 | V7: 2026-06-02 | W7: date_block
A8: ST01 | B8: ST140 | C8: 터미널 높이 검사 | D8: ST01-140-01 | E8: 365301XFB0 | F8: Stator Assys(MV후륜) | G8: 365301XFB0,SFZOT610092 | H8: OK | I8: 46175.373 | J8: 2 | K8: 높이 측정 데이터#2 | L8: T | M8: -0.03 | R8: OK | S8: 검사데이터_조회_터미널단자높이_260504~0602 | T8: 2 | U8: 2026-06-02|주간|LOT=365301XFB0,SFZOT610092 | V8: 2026-06-02 | W8: date_block
A9: ST01 | B9: ST140 | C9: 터미널 높이 검사 | D9: ST01-140-01 | E9: 365301XFB0 | F9: Stator Assys(MV후륜) | G9: 365301XFB0,SFZOT610092 | H9: OK | I9: 46175.373 | J9: 3 | K9: 높이 측정 데이터#3 | L9: T | M9: 0.04 | R9: OK | S9: 검사데이터_조회_터미널단자높이_260504~0602 | T9: 2 | U9: 2026-06-02|주간|LOT=365301XFB0,SFZOT610092 | V9: 2026-06-02 | W9: date_block
A10: ST01 | B10: ST140 | C10: 터미널 높이 검사 | D10: ST01-140-01 | E10: 365301XFB0 | F10: Stator Assys(MV후륜) | G10: 365301XFB0,SFZOT610092 | H10: OK | I10: 46175.373 | J10: 4 | K10: 높이 측정 데이터#4 | L10: T | M10: 0.05 | R10: OK | S10: 검사데이터_조회_터미널단자높이_260504~0602 | T10: 2 | U10: 2026-06-02|주간|LOT=365301XFB0,SFZOT610092 | V10: 2026-06-02 | W10: date_block
A11: ST01 | B11: ST140 | C11: 터미널 높이 검사 | D11: ST01-140-01 | E11: 365301XFB0 | F11: Stator Assys(MV후륜) | G11: 365301XFB0,SFZOT610092 | H11: OK | I11: 46175.373 | J11: 5 | K11: 높이 측정 데이터#5 | L11: T | M11: 0.06 | R11: OK | S11: 검사데이터_조회_터미널단자높이_260504~0602 | T11: 2 | U11: 2026-06-02|주간|LOT=365301XFB0,SFZOT610092 | V11: 2026-06-02 | W11: date_block
A12: ST01 | B12: ST140 | C12: 터미널 높이 검사 | D12: ST01-140-01 | E12: 365301XFB0 | F12: Stator Assys(MV후륜) | G12: 365301XFB0,SFZOT5S0149 | H12: OK | I12: 46168.473 | J12: 1 | K12: 높이 측정 데이터#1 | L12: T | M12: -0.18 | R12: OK | S12: 검사데이터_조회_터미널단자높이_260504~0602 | T12: 3 | U12: 2026-05-26|주간|LOT=365301XFB0,SFZOT5S0149 | V12: 2026-05-26 | W12: date_block
A13: ST01 | B13: ST140 | C13: 터미널 높이 검사 | D13: ST01-140-01 | E13: 365301XFB0 | F13: Stator Assys(MV후륜) | G13: 365301XFB0,SFZOT5S0149 | H13: OK | I13: 46168.473 | J13: 2 | K13: 높이 측정 데이터#2 | L13: T | M13: -0.06 | R13: OK | S13: 검사데이터_조회_터미널단자높이_260504~0602 | T13: 3 | U13: 2026-05-26|주간|LOT=365301XFB0,SFZOT5S0149 | V13: 2026-05-26 | W13: date_block
... A126: ST01 | B126: ST140 | C126: 터미널 높이 검사 | D126: ST01-140-01 | E126: 365301XFB0 | F126: Stator Assys(MV후륜) | G126: 365301XFB0,SFZOT5B0161 | H126: OK | I126: 46154.444 | J126: 5 | K126: 높이 측정 데이터#5 | L126: T | M126: 0.1 | R126: OK | S126: 검사데이터_조회_터미널단자높이_260504~0602 | T126: 25 | U126: 2026-05-12|주간|LOT=365301XFB0,SFZOT5B0161 | V126: 2026-05-12 | W126: date_block

Sheet 판정로그
A1: 우선순위 | B1: 규칙 ID | C1: 판정 내용
A2: 5 | B2: R_CHART_FIRST | C2: R chart unstable -> mean chart interpretation deferred
A3: 6 | B3: DEPLOY_BLOCKED | C3: process not in stable state -> operational control chart deployment not allowed
A4: 14 | B4: NORMality_STRICT | C4: strict_company_mode + non-normal -> cause analysis, action, recollection required
A5: 15 | B5: CAPABILITY_CENTERING | C5: Cp>=1.33 and Cpk<1.33 -> centering improvement recommended
A6: 30 | B6: STAGE_CAPABILITY | C6: stage=mass_production -> CpCpk rule applied (threshold width=1.33, center=1.33)

Sheet 판정요약
A1: 항목 | B1: 판정 결과
A2: 공정상태 | B2: 판정불가
A3: 정규성 | B3: 비정규
A4: 공정능력 | B4: 부족
A5: 관리도 적용 | B5: 불가
A6: 우선 조치 | B6: 데이터 재수집

Sheet 전문가해석
A1: ■ 경영진 요약
A2: 본 공정은 해석용 관리도 기준으로 안정상태가 확인되지 않았습니다. 특히 산포 관리도에서 이상신호가 확인되어 현재 관리한계선을 기반으로 한 현장 운영은 부적절합니다. 이 경우 평균 위치 해석보다 산포 원인 제거가 우선이며, 공정 안정화 후 재수집 데이터를 기준으로 관리한계선을 다시 설정해야 합니다. 공정 산포(폭)는 기준을 만족하나 중심 지수가 부족합니다. 산포 개선보다 규격 중심 대비 평균 위치 조정(centering)이 우선 과제입니다.
A4: ■ 관리도 해석
A5: 관리도에서 관리한계 이탈, 중심선 편향, 과도한 산포 등 4건의 이상 패턴이 감지되었습니다. R(산포) 관리도 불안정 — 평균 관리도 해석 보류, 산포 원인 제거 우선
A7: ■ 정규성 해석
A8: 데이터가 정규분포 가정에서 벗어났습니다. 단순 p-value 판정에 그치지 말고 원인을 파악하고 조치한 뒤 데이터를 재수집하여 재분석하십시오. (검정: Shapiro-Wilk, p=0.0416, QQ: 정규확률도 직선성 양호(R²≈0.976))
A10: ■ 공정능력 해석
A11: 현재 지표는 Cp/Cpk 기준 잠재 공정능력 해석이 중심입니다. 공정 산포(폭)는 기준을 만족하나 중심 지수가 부족합니다. 산포 개선보다 규격 중심 대비 평균 위치 조정(centering)이 우선 과제입니다. Cp=1.394, Cpk=1.167 (기준 Cp/Cpk≥1.33)
A13: ■ 후속조치 가이드
A14: 우선 조치: 데이터 재수집 → 중심 이동
A16: ■ 현장 실무자 해석
A17: 이번 결과는 평균이 약간 벗어난 문제라기보다 공정 흔들림이 크다는 의미에 가깝습니다. 먼저 설비 상태, 치공구, 자재, 측정 이상 여부를 점검해 산포를 키우는 원인을 줄이는 것이 우선입니다.

Sheet AIAG_VDA점검
A1: 점검 항목 | B1: 결과
A2: Pre-control 권고 | B2: X-bar 계열 운용 — Pre-control Chart는 보조 수단으로 검토
A3: 기계성능 필요 | B3: 아니오
A4: Cm/Cmk 모듈 | B4: Cm/Cmk calculation module not implemented yet.
A5: 리포트 완전성 | B5: ✓ 완전
A6: 누락 항목 | B6: 없음
